Workbook

Sheet Price Sheet
A1: Draft starting prices, researched from small-business/local-agency market benchmarks (July 2026). Edit the yellow Suggested Price / Suggested Cost cells to your own numbers, then enter the final values into the Hub's Service Pricing Admin tool. Margin recalculates automatically.
A3: Category | B3: Service | C3: Billing Type | D3: Suggested Price ($) | E3: Suggested Cost ($) | F3: Margin ($) | G3: Notes / Benchmark
A4: Organic Social | B4: Feed Posts (static images, carousels) | C4: Monthly | D4: 350 | E4: 0 | F4: =D4-E4 -> 350
A5: Organic Social | B5: Reels & Short-Form Video | C5: Monthly | D5: 400 | E5: 0 | F5: =D5-E5 -> 400
A6: Organic Social | B6: Stories | C6: Monthly | D6: 150 | E6: 0 | F6: =D6-E6 -> 150
A7: Organic Social | B7: Community Management (responding to comments, DMs, engaging followers) | C7: Monthly | D7: 250 | E7: 0 | F7: =D7-E7 -> 250
A8: Organic Social | B8: Content Calendar Management | C8: Monthly | D8: 200 | E8: 0 | F8: =D8-E8 -> 200
A9: Organic Social | B9: Hashtag Strategy | C9: Monthly | D9: 100 | E9: 0 | F9: =D9-E9 -> 100
A10: Organic Social | B10: Profile Optimization | C10: Monthly | D10: 100 | E10: 0 | F10: =D10-E10 -> 100
A11: Organic Social | B11: Social Listening & Trend Monitoring | C11: Monthly | D11: 150 | E11: 0 | F11: =D11-E11 -> 150
A12: Paid Social | B12: Meta Ads (Facebook + Instagram) | C12: Monthly | D12: 600 | E12: 0 | F12: =D12-E12 -> 600 | G12: Mgmt fee only, excludes ad spend
A13: Paid Social | B13: TikTok Ads | C13: Monthly | D13: 500 | E13: 0 | F13: =D13-E13 -> 500 | G13: Mgmt fee only, excludes ad spend
A14: Paid Social | B14: LinkedIn Ads | C14: Monthly | D14: 600 | E14: 0 | F14: =D14-E14 -> 600 | G14: Mgmt fee only, excludes ad spend
A15: Paid Social | B15: Pinterest Ads | C15: Monthly | D15: 350 | E15: 0 | F15: =D15-E15 -> 350 | G15: Mgmt fee only, excludes ad spend
A16: Paid Social | B16: Snapchat Ads | C16: Monthly | D16: 350 | E16: 0 | F16: =D16-E16 -> 350 | G16: Mgmt fee only, excludes ad spend
A17: Paid Social | B17: Audience Research & Targeting | C17: Monthly | D17: 200 | E17: 0 | F17: =D17-E17 -> 200
A18: Paid Social | B18: Ad Creative Production | C18: Monthly | D18: 300 | E18: 0 | F18: =D18-E18 -> 300
A19: Paid Social | B19: Campaign Setup & Management | C19: One-Time Setup | D19: 500 | E19: 0 | F19: =D19-E19 -> 500
A20: Paid Social | B20: A/B Testing | C20: Monthly | D20: 150 | E20: 0 | F20: =D20-E20 -> 150
A21: Paid Social | B21: Retargeting Campaigns | C21: Monthly | D21: 250 | E21: 0 | F21: =D21-E21 -> 250
A22: Paid Social | B22: Budget Management & Reporting | C22: Monthly | D22: 150 | E22: 0 | F22: =D22-E22 -> 150
A23: Paid Search | B23: Google Ads — Search | C23: Monthly | D23: 700 | E23: 0 | F23: =D23-E23 -> 700 | G23: Mgmt fee only, excludes ad spend
A24: Paid Search | B24: Google Ads — Display | C24: Monthly | D24: 500 | E24: 0 | F24: =D24-E24 -> 500 | G24: Mgmt fee only, excludes ad spend
A25: Paid Search | B25: Google Ads — Performance Max | C25: Monthly | D25: 600 | E25: 0 | F25: =D25-E25 -> 600 | G25: Mgmt fee only, excludes ad spend
A26: Paid Search | B26: Google Ads — Shopping | C26: Monthly | D26: 500 | E26: 0 | F26: =D26-E26 -> 500 | G26: Mgmt fee only, excludes ad spend
A27: Paid Search | B27: Keyword Research | C27: Monthly | D27: 200 | E27: 0 | F27: =D27-E27 -> 200
A28: Paid Search | B28: Ad Copywriting | C28: Monthly | D28: 200 | E28: 0 | F28: =D28-E28 -> 200
A29: Paid Search | B29: Landing Page Recommendations | C29: Monthly | D29: 150 | E29: 0 | F29: =D29-E29 -> 150
A30: Paid Search | B30: Bid Strategy Management | C30: Monthly | D30: 200 | E30: 0 | F30: =D30-E30 -> 200
A31: Paid Search | B31: Conversion Tracking Setup | C31: One-Time Setup | D31: 350 | E31: 0 | F31: =D31-E31 -> 350
A32: Paid Search | B32: Quality Score Optimization | C32: Monthly | D32: 150 | E32: 0 | F32: =D32-E32 -> 150
A33: SEO | B33: On-Page SEO (meta titles, descriptions, headers, content optimization) | C33: Monthly | D33: 400 | E33: 0 | F33: =D33-E33 -> 400
A34: SEO | B34: Technical SEO (site speed, crawlability, schema markup) | C34: Monthly | D34: 350 | E34: 0 | F34: =D34-E34 -> 350
A35: SEO | B35: Local SEO (Google Business Profile, local citations, NAP consistency) | C35: Monthly | D35: 450 | E35: 0 | F35: =D35-E35 -> 450 | G35: Core fit for Revital's local-business client base
A36: SEO | B36: Off-Page SEO (link building, backlink outreach) | C36: Monthly | D36: 400 | E36: 0 | F36: =D36-E36 -> 400
A37: SEO | B37: Keyword Research & Strategy | C37: Monthly | D37: 200 | E37: 0 | F37: =D37-E37 -> 200
A38: SEO | B38: SEO Content Writing (blog posts, landing pages) | C38: Monthly | D38: 350 | E38: 0 | F38: =D38-E38 -> 350
A39: SEO | B39: SEO Audits | C39: One-Time Setup | D39: 500 | E39: 0 | F39: =D39-E39 -> 500
A40: SEO | B40: Google Search Console Management | C40: Monthly | D40: 150 | E40: 0 | F40: =D40-E40 -> 150
A41: SEO | B41: Rank Tracking & Reporting | C41: Monthly | D41: 150 | E41: 0 | F41: =D41-E41 -> 150
...

Sheet Category Summary
A1: Category | B1: # Services | C1: Sum of Suggested Monthly Prices ($) | D1: Sum of Suggested One-Time Setup Prices ($)
A2: Organic Social | B2: =COUNTIF('Price Sheet'!A:A,A2) -> 8 | C2: =SUMIFS('Price Sheet'!D:D,'Price Sheet'!A:A,A2,'Price Sheet'!C:C,"Monthly") -> 1700 | D2: =SUMIFS('Price Sheet'!D:D,'Price Sheet'!A:A,A2,'Price Sheet'!C:C,"One-Time Setup") -> 0
A3: Paid Social | B3: =COUNTIF('Price Sheet'!A:A,A3) -> 11 | C3: =SUMIFS('Price Sheet'!D:D,'Price Sheet'!A:A,A3,'Price Sheet'!C:C,"Monthly") -> 3450 | D3: =SUMIFS('Price Sheet'!D:D,'Price Sheet'!A:A,A3,'Price Sheet'!C:C,"One-Time Setup") -> 500
A4: Paid Search | B4: =COUNTIF('Price Sheet'!A:A,A4) -> 10 | C4: =SUMIFS('Price Sheet'!D:D,'Price Sheet'!A:A,A4,'Price Sheet'!C:C,"Monthly") -> 3200 | D4: =SUMIFS('Price Sheet'!D:D,'Price Sheet'!A:A,A4,'Price Sheet'!C:C,"One-Time Setup") -> 350
A5: SEO | B5: =COUNTIF('Price Sheet'!A:A,A5) -> 9 | C5: =SUMIFS('Price Sheet'!D:D,'Price Sheet'!A:A,A5,'Price Sheet'!C:C,"Monthly") -> 2450 | D5: =SUMIFS('Price Sheet'!D:D,'Price Sheet'!A:A,A5,'Price Sheet'!C:C,"One-Time Setup") -> 500
A6: Email Marketing | B6: =COUNTIF('Price Sheet'!A:A,A6) -> 12 | C6: =SUMIFS('Price Sheet'!D:D,'Price Sheet'!A:A,A6,'Price Sheet'!C:C,"Monthly") -> 1900 | D6: =SUMIFS('Price Sheet'!D:D,'Price Sheet'!A:A,A6,'Price Sheet'!C:C,"One-Time Setup") -> 700
A7: Website Design | B7: =COUNTIF('Price Sheet'!A:A,A7) -> 12 | C7: =SUMIFS('Price Sheet'!D:D,'Price Sheet'!A:A,A7,'Price Sheet'!C:C,"Monthly") -> 1800 | D7: =SUMIFS('Price Sheet'!D:D,'Price Sheet'!A:A,A7,'Price Sheet'!C:C,"One-Time Setup") -> 5200
A8: Inbound Marketing | B8: =COUNTIF('Price Sheet'!A:A,A8) -> 10 | C8: =SUMIFS('Price Sheet'!D:D,'Price Sheet'!A:A,A8,'Price Sheet'!C:C,"Monthly") -> 1150 | D8: =SUMIFS('Price Sheet'!D:D,'Price Sheet'!A:A,A8,'Price Sheet'!C:C,"One-Time Setup") -> 2500
A9: Strategy | B9: =COUNTIF('Price Sheet'!A:A,A9) -> 10 | C9: =SUMIFS('Price Sheet'!D:D,'Price Sheet'!A:A,A9,'Price Sheet'!C:C,"Monthly") -> 2200 | D9: =SUMIFS('Price Sheet'!D:D,'Price Sheet'!A:A,A9,'Price Sheet'!C:C,"One-Time Setup") -> 1500
A10: Software & Tech Stack | B10: =COUNTIF('Price Sheet'!A:A,A10) -> 3 | C10: =SUMIFS('Price Sheet'!D:D,'Price Sheet'!A:A,A10,'Price Sheet'!C:C,"Monthly") -> 389 | D10: =SUMIFS('Price Sheet'!D:D,'Price Sheet'!A:A,A10,'Price Sheet'!C:C,"One-Time Setup") -> 0
A11: Branding & Design | B11: =COUNTIF('Price Sheet'!A:A,A11) -> 8 | C11: =SUMIFS('Price Sheet'!D:D,'Price Sheet'!A:A,A11,'Price Sheet'!C:C,"Monthly") -> 0 | D11: =SUMIFS('Price Sheet'!D:D,'Price Sheet'!A:A,A11,'Price Sheet'!C:C,"One-Time Setup") -> 2350
A12: TOTAL | B12: =SUM(B2:B11) -> 93 | C12: =SUM(C2:C11) -> 18239 | D12: =SUM(D2:D11) -> 13600

Sheet Sources
A1: Benchmark sources used for these suggested starting prices (small-business / local-agency tier, July 2026):
A3: • Social media management pricing — LYFE Marketing, Sprout Social, RecurPost (small biz tier $500-2,000/mo)
A4: • Paid social ad management fees — Webtonic, Stackmatix (mgmt fee separate from ad spend, 10-20% of spend or flat fee)
A5: • Google Ads / PPC management pricing — AMW, Outerbox Design, ALM Corp (small biz tier $500-1,500/mo)
A6: • Local SEO pricing — SEOProfy, Arc4, MultiWebTeam (small biz tier $500-1,500/mo, most common band)
A7: • Email marketing management pricing — Nutshell, AMW, Anthem Software (small biz tier $500-2,000/mo)
A8: • Website design cost — Levitate, GruffyGoat, OneLittleWeb (small biz builds $2,000-8,000)
A9: • HubSpot Marketing Hub pricing — MailSoftly, SendX ($20/seat/mo Starter + contact tiers)
A10: • Sprout Social pricing — Ampifire, CostBench ($199/mo Standard plan)
A11: • Klaviyo pricing — SendX, Omnisend ($20-45/mo entry tier by list size)
A12: • Logo & brand identity pricing — logomakerr.ai, manypixels.co, wearetenet.com (freelance tier $300-2,000; brand identity packages $2,500+ for larger studios/agencies)
